<?xml version="1.0"?>
<robot name="two_wheel_robot">

  <!-- World root link -->
  <link name="world"/>

  <!-- Base Chassis -->
  <link name="chassis">
    <visual>
      <geometry>
        <box size="0.4 0.3 0.1"/>
      </geometry>
      <material name="blue">
        <color rgba="0 0 1 1"/>
      </material>
    </visual>
    <collision>
      <geometry>
        <box size="0.4 0.3 0.1"/>
      </geometry>
    </collision>
    <inertial>
      <mass value="5"/>
      <inertia ixx="0.1" ixy="0" ixz="0" iyy="0.1" iyz="0" izz="0.1"/>
    </inertial>
  </link>

  <!-- Left Wheel -->
  <link name="left_wheel">
    <visual>
      <geometry>
        <cylinder length="0.05" radius="0.07"/>
      </geometry>
      <origin xyz="0 0 0" rpy="1.5708 0 0"/>
      <material name="black">
        <color rgba="0 0 0 1"/>
      </material>
    </visual>
    <collision>
      <geometry>
        <cylinder length="0.05" radius="0.07"/>
      </geometry>
      <origin xyz="0 0 0" rpy="1.5708 0 0"/>
    </collision>
    <inertial>
      <mass value="1"/>
      <inertia ixx="0.01" ixy="0" ixz="0" iyy="0.01" iyz="0" izz="0.01"/>
    </inertial>
  </link>

  <!-- Right Wheel -->
  <link name="right_wheel">
    <visual>
      <geometry>
        <cylinder length="0.05" radius="0.07"/>
      </geometry>
      <origin xyz="0 0 0" rpy="1.5708 0 0"/>
      <material name="black">
        <color rgba="0 0 0 1"/>
      </material>
    </visual>
    <collision>
      <geometry>
        <cylinder length="0.05" radius="0.07"/>
      </geometry>
      <origin xyz="0 0 0" rpy="1.5708 0 0"/>
    </collision>
    <inertial>
      <mass value="1"/>
      <inertia ixx="0.01" ixy="0" ixz="0" iyy="0.01" iyz="0" izz="0.01"/>
    </inertial>
  </link>

  <!-- Fixed joint to world -->
  <joint name="base_fixed_joint" type="fixed">
    <parent link="world"/>
    <child link="chassis"/>
    <origin xyz="0 0 0" rpy="0 0 0"/>
  </joint>

  <!-- Left Wheel Joint -->
  <joint name="left_wheel_joint" type="revolute">
    <parent link="chassis"/>
    <child link="left_wheel"/>
    <origin xyz="0 0.15 -0.05" rpy="0 0 0"/>
    <axis xyz="0 1 0"/>
    <limit lower="-100" upper="100" effort="10" velocity="10"/>
  </joint>

  <!-- Right Wheel Joint -->
  <joint name="right_wheel_joint" type="revolute">
    <parent link="chassis"/>
    <child link="right_wheel"/>
    <origin xyz="0 -0.15 -0.05" rpy="0 0 0"/>
    <axis xyz="0 1 0"/>
    <limit lower="-100" upper="100" effort="10" velocity="10"/>
  </joint>

    <!-- Camera -->
    <link name="camera_link">
        <visual>
            <geometry>
                <box size="0.05 0.05 0.05"/>
            </geometry>
        </visual>
    </link>
    
    <joint name="camera_joint" type="fixed">
        <parent link="chassis"/>
        <child link="camera_link"/>
        <origin xyz="0.15 0 0.25" rpy="0 0 0"/>
    </joint>

    <gazebo reference="camera_link">
        <sensor type="camera" name="camera">
            <always_on>true</always_on>
            <update_rate>30</update_rate>
            <camera>
                <horizontal_fov>1.396</horizontal_fov>
                <image>
                    <width>640</width>
                    <height>480</height>
                    <format>R8G8B8</format>
                </image>
                <clip>
                    <near>0.1</near>
                    <far>100</far>
                </clip>
            </camera>
            <plugin name="gazebo_ros_camera" filename="libgazebo_ros_camera.so">
                <camera_name>camera</camera_name>
                <image_topic_name>image_raw</image_topic_name>
                <frame_name>camera_link</frame_name>
            </plugin>
        </sensor>
    </gazebo>
</robot>
